Workbook

Sheet Vista general
A1: Carros | B1: =COUNTA(Carros!A4:A34) -> 28 | E1: Selección aleatoria carros
A2: Consumo total | B2: =SUM(Caravana!G4:G34)+SUM('Lista Bestias Carga'!G2:G25) -> 126 | E2: 1 | F2: {=INDEX(Caravana!$A$4:$A$100,RANDBETWEEN(1,$B$1),1)} -> Mercancías Punta Arena | G2: 29 | H2: {=INDEX(Caravana!$A$4:$A$100,RANDBETWEEN(1,$B$1),1)} -> Huerto Hagorsson
A3: Viajeros | B3: =COUNTA(Viajeros!A3:A102) -> 80 | E3: 2 | F3: {=INDEX(Caravana!$A$4:$A$100,RANDBETWEEN(1,$B$1),1)} -> Suministros 2 | G3: 30 | H3: {=INDEX(Caravana!$A$4:$A$100,RANDBETWEEN(1,$B$1),1)} -> Mercancías Kalsgard
A4: Viajeros transportados | B4: =CONCAT(CONCAT(SUM(Caravana!H4:H34),"/"),SUM(Caravana!I4:I34)) -> 78/117 | E4: 3 | F4: {=INDEX(Caravana!$A$4:$A$100,RANDBETWEEN(1,$B$1),1)} -> Mercancías Hierro | G4: 31 | H4: {=INDEX(Caravana!$A$4:$A$100,RANDBETWEEN(1,$B$1),1)} -> Familias Kalsgard
E5: 4 | F5: {=INDEX(Caravana!$A$4:$A$100,RANDBETWEEN(1,$B$1),1)} -> Huerto 2 | G5: 32 | H5: {=INDEX(Caravana!$A$4:$A$100,RANDBETWEEN(1,$B$1),1)} -> Real
A6: Bestias | B6: =SUM('Lista Bestias Carga'!E2:E25) -> 63 | E6: 5 | F6: {=INDEX(Caravana!$A$4:$A$100,RANDBETWEEN(1,$B$1),1)} -> Viajeros 2 | G6: 33 | H6: {=INDEX(Caravana!$A$4:$A$100,RANDBETWEEN(1,$B$1),1)} -> Viajeros 1
A7: Salario | B7: =SUM(Viajeros!H3:H102) -> 347 | E7: 6 | F7: {=INDEX(Caravana!$A$4:$A$100,RANDBETWEEN(1,$B$1),1)} -> Huerto 2 | G7: 34 | H7: {=INDEX(Caravana!$A$4:$A$100,RANDBETWEEN(1,$B$1),1)} -> Viajeros 2
E8: 7 | F8: {=INDEX(Caravana!$A$4:$A$100,RANDBETWEEN(1,$B$1),1)} -> Viajeros 1 | G8: 35 | H8: {=INDEX(Caravana!$A$4:$A$100,RANDBETWEEN(1,$B$1),1)} -> Viajeros 3
E9: 8 | F9: {=INDEX(Caravana!$A$4:$A$100,RANDBETWEEN(1,$B$1),1)} -> Taller | G9: 36 | H9: {=INDEX(Caravana!$A$4:$A$100,RANDBETWEEN(1,$B$1),1)} -> Suministros 2
E10: 9 | F10: {=INDEX(Caravana!$A$4:$A$100,RANDBETWEEN(1,$B$1),1)} -> Prisioneros | G10: 37 | H10: {=INDEX(Caravana!$A$4:$A$100,RANDBETWEEN(1,$B$1),1)} -> Suministros 1
E11: 10 | F11: {=INDEX(Caravana!$A$4:$A$100,RANDBETWEEN(1,$B$1),1)} -> Viajeros 4 | G11: 38 | H11: {=INDEX(Caravana!$A$4:$A$100,RANDBETWEEN(1,$B$1),1)} -> Viajeros 4
E12: 11 | F12: {=INDEX(Caravana!$A$4:$A$100,RANDBETWEEN(1,$B$1),1)} -> Suministros 2 | G12: 39 | H12: {=INDEX(Caravana!$A$4:$A$100,RANDBETWEEN(1,$B$1),1)} -> Viajeros 3
E13: 12 | F13: {=INDEX(Caravana!$A$4:$A$100,RANDBETWEEN(1,$B$1),1)} -> Mercancías Hierro | G13: 40 | H13: {=INDEX(Caravana!$A$4:$A$100,RANDBETWEEN(1,$B$1),1)} -> Familias Kalsgard
E14: 13 | F14: {=INDEX(Caravana!$A$4:$A$100,RANDBETWEEN(1,$B$1),1)} -> Bar sin límites | G14: 41 | H14: {=INDEX(Caravana!$A$4:$A$100,RANDBETWEEN(1,$B$1),1)} -> Viajeros grande
E15: 14 | F15: {=INDEX(Caravana!$A$4:$A$100,RANDBETWEEN(1,$B$1),1)} -> Bar sin límites | G15: 42 | H15: {=INDEX(Caravana!$A$4:$A$100,RANDBETWEEN(1,$B$1),1)} -> Viajeros 5
E16: 15 | F16: {=INDEX(Caravana!$A$4:$A$100,RANDBETWEEN(1,$B$1),1)} -> Huerto 1 | G16: 43 | H16: {=INDEX(Caravana!$A$4:$A$100,RANDBETWEEN(1,$B$1),1)} -> Koya
E17: 16 | F17: {=INDEX(Caravana!$A$4:$A$100,RANDBETWEEN(1,$B$1),1)} -> Koya | G17: 44 | H17: {=INDEX(Caravana!$A$4:$A$100,RANDBETWEEN(1,$B$1),1)} -> Viajeros 2
E18: 17 | F18: {=INDEX(Caravana!$A$4:$A$100,RANDBETWEEN(1,$B$1),1)} -> Cómodo 2 | G18: 45 | H18: {=INDEX(Caravana!$A$4:$A$100,RANDBETWEEN(1,$B$1),1)} -> Viajeros 4
E19: 18 | F19: {=INDEX(Caravana!$A$4:$A$100,RANDBETWEEN(1,$B$1),1)} -> Huerto 1 | G19: 46 | H19: {=INDEX(Caravana!$A$4:$A$100,RANDBETWEEN(1,$B$1),1)} -> Mercancías Hierro
... E29: 28 | F29: {=INDEX(Caravana!$A$4:$A$100,RANDBETWEEN(1,$B$1),1)} -> Viajeros 3 | G29: 56 | H29: {=INDEX(Caravana!$A$4:$A$100,RANDBETWEEN(1,$B$1),1)} -> Suministros 1

Sheet Caravana
A1: Carro | C1: Resistencia | F1: Tiro | G1: Consumo total | H1: Pasajeros | J1: Carga | L1: Extra
C2: PG | E2: Dureza
A3: Nombre | B3: Tipo | C3: Daño | D3: Máximo | H3: Ocupado | I3: Máximo | J3: Ocupado | K3: Máximo
A4: =Carros!A4 -> Viajeros 1 | B4: =Carros!B4 -> Carro de viajeros | C4: 0 | D4: =Carros!D4 -> 60 | E4: =Carros!G4 -> 5 | F4: =Tiro!D2 -> SUPERA | G4: =Carros!P4+Hospedaje!D2 -> 10 | H4: =Hospedaje!C2 -> 8 | I4: =Hospedaje!B2 -> 8 | J4: =Carga!C2 -> 4 | K4: =Carga!B2 -> 5 | L4: =IFERROR(VLOOKUP(B4,'Lista Carros'!$A$3:$K$26,11,False),"") -> Otorga +1 CA a la caravana
A5: =Carros!A5 -> Viajeros 2 | B5: =Carros!B5 -> Carro de viajeros | C5: 0 | D5: =Carros!D5 -> 60 | E5: =Carros!G5 -> 5 | F5: =Tiro!D3 -> SUPERA | G5: =Carros!P5+Hospedaje!D3 -> 9 | H5: =Hospedaje!C3 -> 7 | I5: =Hospedaje!B3 -> 8 | J5: =Carga!C3 -> 3 | K5: =Carga!B3 -> 5 | L5: =IFERROR(VLOOKUP(B5,'Lista Carros'!$A$3:$K$26,11,False),"") -> Otorga +1 CA a la caravana
A6: =Carros!A6 -> Viajeros 3 | B6: =Carros!B6 -> Carro de viajeros | C6: 0 | D6: =Carros!D6 -> 60 | E6: =Carros!G6 -> 5 | F6: =Tiro!D4 -> SUPERA | G6: =Carros!P6+Hospedaje!D4 -> 9 | H6: =Hospedaje!C4 -> 7 | I6: =Hospedaje!B4 -> 8 | J6: =Carga!C4 -> 3 | K6: =Carga!B4 -> 5 | L6: =IFERROR(VLOOKUP(B6,'Lista Carros'!$A$3:$K$26,11,False),"") -> Otorga +1 CA a la caravana
A7: =Carros!A7 -> Viajeros 4 | B7: =Carros!B7 -> Carro de viajeros | C7: 0 | D7: =Carros!D7 -> 60 | E7: =Carros!G7 -> 5 | F7: =Tiro!D5 -> SUPERA | G7: =Carros!P7+Hospedaje!D5 -> 9 | H7: =Hospedaje!C5 -> 7 | I7: =Hospedaje!B5 -> 8 | J7: =Carga!C5 -> 4 | K7: =Carga!B5 -> 5 | L7: =IFERROR(VLOOKUP(B7,'Lista Carros'!$A$3:$K$26,11,False),"") -> Otorga +1 CA a la caravana
A8: =Carros!A8 -> Viajeros 5 | B8: =Carros!B8 -> Carro de viajeros | C8: 0 | D8: =Carros!D8 -> 60 | E8: =Carros!G8 -> 5 | F8: =Tiro!D6 -> SUPERA | G8: =Carros!P8+Hospedaje!D6 -> 8 | H8: =Hospedaje!C6 -> 6 | I8: =Hospedaje!B6 -> 8 | J8: =Carga!C6 -> 4 | K8: =Carga!B6 -> 5 | L8: =IFERROR(VLOOKUP(B8,'Lista Carros'!$A$3:$K$26,11,False),"") -> Otorga +1 CA a la caravana
A9: =Carros!A9 -> Prisioneros | B9: =Carros!B9 -> Carro de prisioneros | C9: 9 | D9: =Carros!D9 -> 60 | E9: =Carros!G9 -> 5 | F9: =Tiro!D7 -> SUPERA | G9: =Carros!P9+Hospedaje!D7 -> 2 | H9: =Hospedaje!C7 -> 0 | I9: =Hospedaje!B7 -> 10 | J9: =Carga!C7 -> 0 | K9: =Carga!B7 -> 2 | L9: =IFERROR(VLOOKUP(B9,'Lista Carros'!$A$3:$K$26,11,False),"") -> Otorga +2 a la Seguridad de la caravana
A10: =Carros!A10 -> Zoo | B10: =Carros!B10 -> Carro zoológico | C10: 0 | D10: =Carros!D10 -> 60 | E10: =Carros!G10 -> 5 | F10: =Tiro!D8 -> SUPERA | G10: =Carros!P10+Hospedaje!D8 -> 3 | H10: =Hospedaje!C8 -> 8.5 | I10: =Hospedaje!B8 -> 10 | J10: =Carga!C8 -> 0 | K10: =Carga!B8 -> 2 | L10: =IFERROR(VLOOKUP(B10,'Lista Carros'!$A$3:$K$26,11,False),"") -> No puede llevar humanoides
A11: =Carros!A11 -> Familias Kalsgard | B11: =Carros!B11 -> Carruaje familiar | C11: 0 | D11: =Carros!D11 -> 60 | E11: =Carros!G11 -> 5 | F11: =Tiro!D9 -> SUPERA | G11: =Carros!P11+Hospedaje!D9 -> 10 | H11: =Hospedaje!C9 -> 6.5 | I11: =Hospedaje!B9 -> 6 | J11: =Carga!C9 -> 0 | K11: =Carga!B9 -> 5 | L11: =IFERROR(VLOOKUP(B11,'Lista Carros'!$A$3:$K$26,11,False),"") -> Criaturas pequeñas cuentan como ½
A12: =Carros!A12 -> Mercancías Hierro | B12: =Carros!B12 -> Carro de mercancías | C12: 0 | D12: =Carros!D12 -> 60 | E12: =Carros!G12 -> 5 | F12: =Tiro!D10 -> SUPERA | G12: =Carros!P12+Hospedaje!D10 -> 1 | H12: =Hospedaje!C10 -> 0 | I12: =Hospedaje!B10 -> 1 | J12: =Carga!C10 -> 12 | K12: =Carga!B10 -> 13 | L12: =IFERROR(VLOOKUP(B12,'Lista Carros'!$A$3:$K$26,11,False),"")
A13: =Carros!A13 -> Mercancías General | B13: =Carros!B13 -> Carro de mercancías | C13: 3 | D13: =Carros!D13 -> 60 | E13: =Carros!G13 -> 5 | F13: =Tiro!D11 -> SUPERA | G13: =Carros!P13+Hospedaje!D11 -> 1 | H13: =Hospedaje!C11 -> 0 | I13: =Hospedaje!B11 -> 1 | J13: =Carga!C11 -> 13 | K13: =Carga!B11 -> 13 | L13: =IFERROR(VLOOKUP(B13,'Lista Carros'!$A$3:$K$26,11,False),"")
A14: =Carros!A14 -> Mercancías Punta Arena | B14: =Carros!B14 -> Carro de mercancías | C14: 1 | D14: =Carros!D14 -> 60 | E14: =Carros!G14 -> 5 | F14: =Tiro!D12 -> SUPERA | G14: =Carros!P14+Hospedaje!D12 -> 1 | H14: =Hospedaje!C12 -> 0 | I14: =Hospedaje!B12 -> 1 | J14: =Carga!C12 -> 13 | K14: =Carga!B12 -> 13 | L14: =IFERROR(VLOOKUP(B14,'Lista Carros'!$A$3:$K$26,11,False),"")
A15: =Carros!A15 -> Mercancías Kalsgard | B15: =Carros!B15 -> Carro de mercancías específicas | C15: 0 | D15: =Carros!D15 -> 60 | E15: =Carros!G15 -> 5 | F15: =Tiro!D13 -> SUPERA | G15: =Carros!P15+Hospedaje!D13 -> 1 | H15: =Hospedaje!C13 -> 0 | I15: =Hospedaje!B13 -> 1 | J15: =Carga!C13 -> 26 | K15: =Carga!B13 -> 26 | L15: =IFERROR(VLOOKUP(B15,'Lista Carros'!$A$3:$K$26,11,False),"") -> Solo 1 tipo de mercancía específica
... A31: =Carros!A31 -> Viajeros grande | B31: =Carros!B31 -> Carro de viajeros | C31: 0 | D31: =Carros!D31 -> 60 | E31: =Carros!G31 -> 5 | F31: =Tiro!D29 -> SUPERA | G31: =Carros!P31+Hospedaje!D29 -> 11 | H31: =Hospedaje!C29 -> 9 | I31: =Hospedaje!B29 -> 10 | J31: =Carga!C29 -> 0 | K31: =Carga!B29 -> 5 | L31: =IFERROR(VLOOKUP(B31,'Lista Carros'!$A$3:$K$26,11,False),"") -> Otorga +1 CA a la caravana
A32: =Carros!A32 | B32: =Carros!B32 | D32: =Carros!D32 -> 0 | E32: =Carros!G32 -> 0 | F32: =Tiro!D30 -> SUPERA | G32: =Carros!P32+Hospedaje!D30 -> 0 | H32: =Hospedaje!C30 -> 0 | I32: =Hospedaje!B30 | J32: =Carga!C30 -> 0 | K32: =Carga!B30 | L32: =IFERROR(VLOOKUP(B32,'Lista Carros'!$A$3:$K$26,11,False),"")
A33: =Carros!A33 | B33: =Carros!B33 | D33: =Carros!D33 -> 0 | E33: =Carros!G33 -> 0 | F33: =Tiro!D31 -> SUPERA | G33: =Carros!P33+Hospedaje!D31 -> 0 | H33: =Hospedaje!C31 -> 0 | I33: =Hospedaje!B31 | J33: =Carga!C31 -> 0 | K33: =Carga!B31 | L33: =IFERROR(VLOOKUP(B33,'Lista Carros'!$A$3:$K$26,11,False),"")
A34: =Carros!A34 | B34: =Carros!B34 | D34: =Carros!D34 -> 0 | E34: =Carros!G34 -> 0 | F34: =Tiro!D32 -> SUPERA | G34: =Carros!P34+Hospedaje!D32 -> 0 | H34: =Hospedaje!C32 -> 0 | I34: =Hospedaje!B32 | J34: =Carga!C32 -> 0 | K34: =Carga!B32 | L34: =IFERROR(VLOOKUP(B34,'Lista Carros'!$A$3:$K$26,11,False),"")

Sheet Viajeros
J1: Roles posibles
A2: Nombre | B2: Descripción | C2: Rol actual | D2: Rol adicional | E2: Carro | F2: Consumo | G2: Espacio | H2: Salario | I2: Con cama
A3: Renji | C3: Boticario | D3: Guarda | E3: {=IFERROR(INDEX(Hospedaje!$A$2:$A$32, MATCH(TRUE, BYROW(Hospedaje!$E$2:$S$32, LAMBDA(fila, COUNTIF(fila, A3)>0)), 0)),"-")} -> Cómodo 1 | F3: 1 | G3: 1 | I3: =IF(COUNTIF(Hospedaje!$E$2:$S$32,A3)=1,"Sí",IF(COUNTIF(Hospedaje!$E$2:$S$32,A3)=0,"No","DUPLICADO")) -> Sí | J3: Guarda | K3: Boticario | AD3: Pasajero
A4: O Chin Chin | C4: Boticario | D4: Explorador nocturno | E4: {=IFERROR(INDEX(Hospedaje!$A$2:$A$32, MATCH(TRUE, BYROW(Hospedaje!$E$2:$S$32, LAMBDA(fila, COUNTIF(fila, A4)>0)), 0)),"-")} -> Real | F4: 1 | G4: 1 | I4: =IF(COUNTIF(Hospedaje!$E$2:$S$32,A4)=1,"Sí",IF(COUNTIF(Hospedaje!$E$2:$S$32,A4)=0,"No","DUPLICADO")) -> Sí | J4: Boticario | K4: Explorador nocturno | AD4: Pasajero
A5: Lewis | C5: Guía | D5: Comediante | E5: {=IFERROR(INDEX(Hospedaje!$A$2:$A$32, MATCH(TRUE, BYROW(Hospedaje!$E$2:$S$32, LAMBDA(fila, COUNTIF(fila, A5)>0)), 0)),"-")} -> Bar sin límites | F5: 1 | G5: 1 | I5: =IF(COUNTIF(Hospedaje!$E$2:$S$32,A5)=1,"Sí",IF(COUNTIF(Hospedaje!$E$2:$S$32,A5)=0,"No","DUPLICADO")) -> Sí | J5: Guía | K5: Comediante | AD5: Pasajero
A6: Irgadriel | C6: Explorador nocturno | D6: Boticario | E6: {=IFERROR(INDEX(Hospedaje!$A$2:$A$32, MATCH(TRUE, BYROW(Hospedaje!$E$2:$S$32, LAMBDA(fila, COUNTIF(fila, A6)>0)), 0)),"-")} -> Cómodo 2 | F6: 1 | G6: 1 | I6: =IF(COUNTIF(Hospedaje!$E$2:$S$32,A6)=1,"Sí",IF(COUNTIF(Hospedaje!$E$2:$S$32,A6)=0,"No","DUPLICADO")) -> Sí | J6: Boticario | K6: Explorador nocturno | AD6: Pasajero
A7: Virihane | C7: Encargado de suministros | D7: Artesano | E7: {=IFERROR(INDEX(Hospedaje!$A$2:$A$32, MATCH(TRUE, BYROW(Hospedaje!$E$2:$S$32, LAMBDA(fila, COUNTIF(fila, A7)>0)), 0)),"-")} -> Cómodo 1 | F7: 1 | G7: 1 | I7: =IF(COUNTIF(Hospedaje!$E$2:$S$32,A7)=1,"Sí",IF(COUNTIF(Hospedaje!$E$2:$S$32,A7)=0,"No","DUPLICADO")) -> Sí | J7: Artesano | K7: Encargado de suministros | AD7: Pasajero
A8: Hiriko | C8: Guarda | D8: Artesano | E8: {=IFERROR(INDEX(Hospedaje!$A$2:$A$32, MATCH(TRUE, BYROW(Hospedaje!$E$2:$S$32, LAMBDA(fila, COUNTIF(fila, A8)>0)), 0)),"-")} -> Real | F8: 1 | G8: 1 | I8: =IF(COUNTIF(Hospedaje!$E$2:$S$32,A8)=1,"Sí",IF(COUNTIF(Hospedaje!$E$2:$S$32,A8)=0,"No","DUPLICADO")) -> Sí | J8: Guarda | K8: Carrero | L8: Carretero | M8: Explorador nocturno | N8: Artesano | O8: Comerciante | AD8: Pasajero
A9: Shalelu | C9: Batidor | E9: {=IFERROR(INDEX(Hospedaje!$A$2:$A$32, MATCH(TRUE, BYROW(Hospedaje!$E$2:$S$32, LAMBDA(fila, COUNTIF(fila, A9)>0)), 0)),"-")} -> Cómodo 2 | F9: 1 | G9: 1 | I9: =IF(COUNTIF(Hospedaje!$E$2:$S$32,A9)=1,"Sí",IF(COUNTIF(Hospedaje!$E$2:$S$32,A9)=0,"No","DUPLICADO")) -> Sí | J9: Guarda | K9: Batidor | L9: Explorador nocturno | M9: Leñador | N9: Nevero | O9: Meteorólogo | P9: Lanzador de conjuros | AD9: Pasajero
A10: Sandru | C10: Carretero | E10: {=IFERROR(INDEX(Hospedaje!$A$2:$A$32, MATCH(TRUE, BYROW(Hospedaje!$E$2:$S$32, LAMBDA(fila, COUNTIF(fila, A10)>0)), 0)),"-")} -> Cómodo 1 | F10: 1 | G10: 1 | I10: =IF(COUNTIF(Hospedaje!$E$2:$S$32,A10)=1,"Sí",IF(COUNTIF(Hospedaje!$E$2:$S$32,A10)=0,"No","DUPLICADO")) -> Sí | J10: Guarda | K10: Explorador nocturno | L10: Comerciante | M10: Carrero | N10: Carretero | O10: Domador | P10: Diplomático | Q10: Cronista | AD10: Pasajero
A11: Ameiko | C11: Comediante | E11: {=IFERROR(INDEX(Hospedaje!$A$2:$A$32, MATCH(TRUE, BYROW(Hospedaje!$E$2:$S$32, LAMBDA(fila, COUNTIF(fila, A11)>0)), 0)),"-")} -> Real | F11: 1 | G11: 1 | I11: =IF(COUNTIF(Hospedaje!$E$2:$S$32,A11)=1,"Sí",IF(COUNTIF(Hospedaje!$E$2:$S$32,A11)=0,"No","DUPLICADO")) -> Sí | J11: Animador itinerante | K11: Comediante | L11: Comerciante | M11: Guarda | N11: Explorador nocturno | O11: Pasajero | P11: Cocinero | Q11: Cronista | R11: Lanzador de conjuros | AD11: Pasajero
A12: Koya | C12: Adivino | E12: {=IFERROR(INDEX(Hospedaje!$A$2:$A$32, MATCH(TRUE, BYROW(Hospedaje!$E$2:$S$32, LAMBDA(fila, COUNTIF(fila, A12)>0)), 0)),"-")} -> Koya | F12: 1 | G12: 1 | I12: =IF(COUNTIF(Hospedaje!$E$2:$S$32,A12)=1,"Sí",IF(COUNTIF(Hospedaje!$E$2:$S$32,A12)=0,"No","DUPLICADO")) -> Sí | J12: Adivino | K12: Sanador | L12: Guarda | M12: Explorador nocturno | N12: Lanzador de conjuros | O12: Diplomático | AD12: Pasajero
A13: Bevelek | B13: Conductor inicial | C13: Carretero | E13: {=IFERROR(INDEX(Hospedaje!$A$2:$A$32, MATCH(TRUE, BYROW(Hospedaje!$E$2:$S$32, LAMBDA(fila, COUNTIF(fila, A13)>0)), 0)),"-")} -> Viajeros 1 | F13: 1 | G13: 1 | I13: =IF(COUNTIF(Hospedaje!$E$2:$S$32,A13)=1,"Sí",IF(COUNTIF(Hospedaje!$E$2:$S$32,A13)=0,"No","DUPLICADO")) -> Sí | J13: Carretero | K13: Carrero | AD13: Pasajero
A14: Vankor | B14: Conductor inicial | C14: Carretero | E14: {=IFERROR(INDEX(Hospedaje!$A$2:$A$32, MATCH(TRUE, BYROW(Hospedaje!$E$2:$S$32, LAMBDA(fila, COUNTIF(fila, A14)>0)), 0)),"-")} -> Viajeros 1 | F14: 1 | G14: 1 | I14: =IF(COUNTIF(Hospedaje!$E$2:$S$32,A14)=1,"Sí",IF(COUNTIF(Hospedaje!$E$2:$S$32,A14)=0,"No","DUPLICADO")) -> Sí | J14: Carretero | K14: Carrero | AD14: Pasajero
A15: Velani Korrast | B15: Random | C15: Carretero | E15: {=IFERROR(INDEX(Hospedaje!$A$2:$A$32, MATCH(TRUE, BYROW(Hospedaje!$E$2:$S$32, LAMBDA(fila, COUNTIF(fila, A15)>0)), 0)),"-")} -> Viajeros 1 | F15: 1 | G15: 1 | H15: 10 | I15: =IF(COUNTIF(Hospedaje!$E$2:$S$32,A15)=1,"Sí",IF(COUNTIF(Hospedaje!$E$2:$S$32,A15)=0,"No","DUPLICADO")) -> Sí | J15: Carretero | AD15: Pasajero
A16: Seya Numari | B16: Random | C16: Carretero | E16: {=IFERROR(INDEX(Hospedaje!$A$2:$A$32, MATCH(TRUE, BYROW(Hospedaje!$E$2:$S$32, LAMBDA(fila, COUNTIF(fila, A16)>0)), 0)),"-")} -> Viajeros 1 | F16: 1 | G16: 1 | H16: 10 | I16: =IF(COUNTIF(Hospedaje!$E$2:$S$32,A16)=1,"Sí",IF(COUNTIF(Hospedaje!$E$2:$S$32,A16)=0,"No","DUPLICADO")) -> Sí | J16: Carretero | AD16: Pasajero
A17: Ormund Gevren | B17: Random | C17: Carretero | E17: {=IFERROR(INDEX(Hospedaje!$A$2:$A$32, MATCH(TRUE, BYROW(Hospedaje!$E$2:$S$32, LAMBDA(fila, COUNTIF(fila, A17)>0)), 0)),"-")} -> Viajeros 1 | F17: 1 | G17: 1 | H17: 10 | I17: =IF(COUNTIF(Hospedaje!$E$2:$S$32,A17)=1,"Sí",IF(COUNTIF(Hospedaje!$E$2:$S$32,A17)=0,"No","DUPLICADO")) -> Sí | J17: Carretero | AD17: Pasajero
A18: Caurrin Whesterwill | B18: Molinero de Punta Arena | C18: Encargado de suministros | E18: {=IFERROR(INDEX(Hospedaje!$A$2:$A$32, MATCH(TRUE, BYROW(Hospedaje!$E$2:$S$32, LAMBDA(fila, COUNTIF(fila, A18)>0)), 0)),"-")} -> Viajeros 1 | F18: 1 | G18: 1 | H18: 75 | I18: =IF(COUNTIF(Hospedaje!$E$2:$S$32,A18)=1,"Sí",IF(COUNTIF(Hospedaje!$E$2:$S$32,A18)=0,"No","DUPLICADO")) -> Sí | J18: Encargado de suministros | AD18: Pasajero
A19: Clark (perro Lewis) | C19: Explorador nocturno | E19: {=IFERROR(INDEX(Hospedaje!$A$2:$A$32, MATCH(TRUE, BYROW(Hospedaje!$E$2:$S$32, LAMBDA(fila, COUNTIF(fila, A19)>0)), 0)),"-")} -> Bar sin límites | F19: 1 | G19: 0.5 | I19: =IF(COUNTIF(Hospedaje!$E$2:$S$32,A19)=1,"Sí",IF(COUNTIF(Hospedaje!$E$2:$S$32,A19)=0,"No","DUPLICADO")) -> Sí | J19: Guarda | K19: Explorador nocturno | L19: Batidor | AD19: Pasajero
A20: Ralvio Dorran | B20: Borrachín | C20: Cocinero | E20: {=IFERROR(INDEX(Hospedaje!$A$2:$A$32, MATCH(TRUE, BYROW(Hospedaje!$E$2:$S$32, LAMBDA(fila, COUNTIF(fila, A20)>0)), 0)),"-")} -> Bar sin límites | F20: 1 | G20: 1 | I20: =IF(COUNTIF(Hospedaje!$E$2:$S$32,A20)=1,"Sí",IF(COUNTIF(Hospedaje!$E$2:$S$32,A20)=0,"No","DUPLICADO")) -> Sí | J20: Cocinero | AD20: Pasajero
A21: Erivo | B21: Semiorca hechicera | C21: Lanzador de conjuros | E21: {=IFERROR(INDEX(Hospedaje!$A$2:$A$32, MATCH(TRUE, BYROW(Hospedaje!$E$2:$S$32, LAMBDA(fila, COUNTIF(fila, A21)>0)), 0)),"-")} -> Escuela | F21: 1 | G21: 1 | I21: =IF(COUNTIF(Hospedaje!$E$2:$S$32,A21)=1,"Sí",IF(COUNTIF(Hospedaje!$E$2:$S$32,A21)=0,"No","DUPLICADO")) -> Sí | J21: Lanzador de conjuros | K21: Guarda | L21: Explorador nocturno | M21: Batidor | N21: Leñador | O21: Nevero | AD21: Pasajero
A22: Devoramundos | C22: Pasajero | E22: {=IFERROR(INDEX(Hospedaje!$A$2:$A$32, MATCH(TRUE, BYROW(Hospedaje!$E$2:$S$32, LAMBDA(fila, COUNTIF(fila, A22)>0)), 0)),"-")} -> Real | F22: 1 | G22: 0 | I22: =IF(COUNTIF(Hospedaje!$E$2:$S$32,A22)=1,"Sí",IF(COUNTIF(Hospedaje!$E$2:$S$32,A22)=0,"No","DUPLICADO")) -> Sí | J22: Guarda | K22: Explorador nocturno | L22: Esclavista | M22: Lanzador de conjuros | N22: Profesor | O22: Instructor | P22: Artesano | AD22: Pasajero
A23: Korrin Feldane | B23: Random | C23: Carretero | E23: {=IFERROR(INDEX(Hospedaje!$A$2:$A$32, MATCH(TRUE, BYROW(Hospedaje!$E$2:$S$32, LAMBDA(fila, COUNTIF(fila, A23)>0)), 0)),"-")} -> Viajeros 5 | F23: 1 | G23: 1 | H23: 10 | I23: =IF(COUNTIF(Hospedaje!$E$2:$S$32,A23)=1,"Sí",IF(COUNTIF(Hospedaje!$E$2:$S$32,A23)=0,"No","DUPLICADO")) -> Sí | J23: Carretero | AD23: Pasajero
A24: Spivey | C24: Sanador | E24: {=IFERROR(INDEX(Hospedaje!$A$2:$A$32, MATCH(TRUE, BYROW(Hospedaje!$E$2:$S$32, LAMBDA(fila, COUNTIF(fila, A24)>0)), 0)),"-")} -> Koya | F24: 0 | G24: 0 | I24: =IF(COUNTIF(Hospedaje!$E$2:$S$32,A24)=1,"Sí",IF(COUNTIF(Hospedaje!$E$2:$S$32,A24)=0,"No","DUPLICADO")) -> Sí | J24: Sanador | K24: Guarda | L24: Explorador nocturno | M24: Adivino | N24: Lanzador de conjuros | O24: Boticario | P24: Animador itinerante | Q24: Comediante | AD24: Pasajero
A25: Eirik "Cuervo Roto" | B25: Proscritos ulfen | C25: Batidor | E25: {=IFERROR(INDEX(Hospedaje!$A$2:$A$32, MATCH(TRUE, BYROW(Hospedaje!$E$2:$S$32, LAMBDA(fila, COUNTIF(fila, A25)>0)), 0)),"-")} -> Viajeros grande | F25: 1 | G25: 1 | I25: =IF(COUNTIF(Hospedaje!$E$2:$S$32,A25)=1,"Sí",IF(COUNTIF(Hospedaje!$E$2:$S$32,A25)=0,"No","DUPLICADO")) -> Sí | J25: Batidor | AD25: Pasajero
A26: Takorr Senda Quemada | B26: Proscritos shoanti | C26: Meteorólogo | E26: {=IFERROR(INDEX(Hospedaje!$A$2:$A$32, MATCH(TRUE, BYROW(Hospedaje!$E$2:$S$32, LAMBDA(fila, COUNTIF(fila, A26)>0)), 0)),"-")} -> Viajeros grande | F26: 1 | G26: 1 | I26: =IF(COUNTIF(Hospedaje!$E$2:$S$32,A26)=1,"Sí",IF(COUNTIF(Hospedaje!$E$2:$S$32,A26)=0,"No","DUPLICADO")) -> Sí | J26: Meteorólogo | AD26: Pasajero
A27: Jorgaan de la Roca Blanca | B27: Proscritos ulfen | C27: Artesano | E27: {=IFERROR(INDEX(Hospedaje!$A$2:$A$32, MATCH(TRUE, BYROW(Hospedaje!$E$2:$S$32, LAMBDA(fila, COUNTIF(fila, A27)>0)), 0)),"-")} -> Viajeros grande | F27: 1 | G27: 1 | I27: =IF(COUNTIF(Hospedaje!$E$2:$S$32,A27)=1,"Sí",IF(COUNTIF(Hospedaje!$E$2:$S$32,A27)=0,"No","DUPLICADO")) -> Sí | J27: Artesano | AD27: Pasajero
A28: Ketaek pasos cortos | B28: Proscritos shoanti | C28: Cocinero | E28: {=IFERROR(INDEX(Hospedaje!$A$2:$A$32, MATCH(TRUE, BYROW(Hospedaje!$E$2:$S$32, LAMBDA(fila, COUNTIF(fila, A28)>0)), 0)),"-")} -> Viajeros grande | F28: 1 | G28: 1 | I28: =IF(COUNTIF(Hospedaje!$E$2:$S$32,A28)=1,"Sí",IF(COUNTIF(Hospedaje!$E$2:$S$32,A28)=0,"No","DUPLICADO")) -> Sí | J28: Cocinero | AD28: Pasajero
A29: Sigmund "Ojos de Hielo" | B29: Proscritos ulfen | C29: Domador | E29: {=IFERROR(INDEX(Hospedaje!$A$2:$A$32, MATCH(TRUE, BYROW(Hospedaje!$E$2:$S$32, LAMBDA(fila, COUNTIF(fila, A29)>0)), 0)),"-")} -> Viajeros grande | F29: 1 | G29: 1 | I29: =IF(COUNTIF(Hospedaje!$E$2:$S$32,A29)=1,"Sí",IF(COUNTIF(Hospedaje!$E$2:$S$32,A29)=0,"No","DUPLICADO")) -> Sí | J29: Domador | AD29: Pasajero
A30: Yrja Vientonegro | B30: Proscritos ulfen | C30: Carretero | E30: {=IFERROR(INDEX(Hospedaje!$A$2:$A$32, MATCH(TRUE, BYROW(Hospedaje!$E$2:$S$32, LAMBDA(fila, COUNTIF(fila, A30)>0)), 0)),"-")} -> Viajeros grande | F30: 1 | G30: 1 | I30: =IF(COUNTIF(Hospedaje!$E$2:$S$32,A30)=1,"Sí",IF(COUNTIF(Hospedaje!$E$2:$S$32,A30)=0,"No","DUPLICADO")) -> Sí | J30: Carretero | AD30: Pasajero
A31: Ashka Cantoceniza | B31: Proscritos shoanti | C31: Cronista | E31: {=IFERROR(INDEX(Hospedaje!$A$2:$A$32, MATCH(TRUE, BYROW(Hospedaje!$E$2:$S$32, LAMBDA(fila, COUNTIF(fila, A31)>0)), 0)),"-")} -> Viajeros grande | F31: 1 | G31: 1 | I31: =IF(COUNTIF(Hospedaje!$E$2:$S$32,A31)=1,"Sí",IF(COUNTIF(Hospedaje!$E$2:$S$32,A31)=0,"No","DUPLICADO")) -> Sí | J31: Cronista | AD31: Pasajero
A32: Freydis Manodura | B32: Proscritos ulfen | C32: Batidor | E32: {=IFERROR(INDEX(Hospedaje!$A$2:$A$32, MATCH(TRUE, BYROW(Hospedaje!$E$2:$S$32, LAMBDA(fila, COUNTIF(fila, A32)>0)), 0)),"-")} -> Viajeros grande | F32: 1 | G32: 1 | I32: =IF(COUNTIF(Hospedaje!$E$2:$S$32,A32)=1,"Sí",IF(COUNTIF(Hospedaje!$E$2:$S$32,A32)=0,"No","DUPLICADO")) -> Sí | J32: Batidor | AD32: Pasajero
A33: Cholna de las Lluvias | B33: Proscritos shoanti | C33: Boticario | E33: {=IFERROR(INDEX(Hospedaje!$A$2:$A$32, MATCH(TRUE, BYROW(Hospedaje!$E$2:$S$32, LAMBDA(fila, COUNTIF(fila, A33)>0)), 0)),"-")} -> Viajeros grande | F33: 1 | G33: 1 | I33: =IF(COUNTIF(Hospedaje!$E$2:$S$32,A33)=1,"Sí",IF(COUNTIF(Hospedaje!$E$2:$S$32,A33)=0,"No","DUPLICADO")) -> Sí | J33: Boticario | AD33: Pasajero
A34: Kelda | C34: Carretero | E34: {=IFERROR(INDEX(Hospedaje!$A$2:$A$32, MATCH(TRUE, BYROW(Hospedaje!$E$2:$S$32, LAMBDA(fila, COUNTIF(fila, A34)>0)), 0)),"-")} -> Cómodo 1 | F34: 1 | G34: 1 | H34: 80 | I34: =IF(COUNTIF(Hospedaje!$E$2:$S$32,A34)=1,"Sí",IF(COUNTIF(Hospedaje!$E$2:$S$32,A34)=0,"No","DUPLICADO")) -> Sí | J34: Guarda | K34: Batidor | L34: Nevero | M34: Leñador | N34: Domador | O34: Explorador nocturno | P34: Carretero | AD34: Pasajero
A35: Frinn (huérfano) | B35: Niño huérfano de Tomgruv | C35: Pasajero | E35: {=IFERROR(INDEX(Hospedaje!$A$2:$A$32, MATCH(TRUE, BYROW(Hospedaje!$E$2:$S$32, LAMBDA(fila, COUNTIF(fila, A35)>0)), 0)),"-")} -> Cómodo 2 | F35: 1 | G35: 0.5 | I35: =IF(COUNTIF(Hospedaje!$E$2:$S$32,A35)=1,"Sí",IF(COUNTIF(Hospedaje!$E$2:$S$32,A35)=0,"No","DUPLICADO")) -> Sí | J35: Pasajero | AD35: Pasajero
A36: Skøra (huérfana) | B36: Niña huérfano de Tomgruv | C36: Pasajero | E36: {=IFERROR(INDEX(Hospedaje!$A$2:$A$32, MATCH(TRUE, BYROW(Hospedaje!$E$2:$S$32, LAMBDA(fila, COUNTIF(fila, A36)>0)), 0)),"-")} -> Cómodo 2 | F36: 1 | G36: 0.5 | I36: =IF(COUNTIF(Hospedaje!$E$2:$S$32,A36)=1,"Sí",IF(COUNTIF(Hospedaje!$E$2:$S$32,A36)=0,"No","DUPLICADO")) -> Sí | J36: Pasajero | AD36: Pasajero
A37: Krixi cincadientes | B37: Kobol de Tomgruv | C37: Sirviente | E37: {=IFERROR(INDEX(Hospedaje!$A$2:$A$32, MATCH(TRUE, BYROW(Hospedaje!$E$2:$S$32, LAMBDA(fila, COUNTIF(fila, A37)>0)), 0)),"-")} -> Viajeros 1 | F37: 1 | G37: 1 | I37: =IF(COUNTIF(Hospedaje!$E$2:$S$32,A37)=1,"Sí",IF(COUNTIF(Hospedaje!$E$2:$S$32,A37)=0,"No","DUPLICADO")) -> Sí | J37: Sirviente | AD37: Pasajero
A38: Caballos Yakutos | C38: Animales de tiro | E38: {=IFERROR(INDEX(Hospedaje!$A$2:$A$32, MATCH(TRUE, BYROW(Hospedaje!$E$2:$S$32, LAMBDA(fila, COUNTIF(fila, A38)>0)), 0)),"-")} -> Zoo | F38: 0 | G38: 6 | I38: =IF(COUNTIF(Hospedaje!$E$2:$S$32,A38)=1,"Sí",IF(COUNTIF(Hospedaje!$E$2:$S$32,A38)=0,"No","DUPLICADO")) -> Sí | J38: Animales de tiro | AD38: Pasajero
A39: Miaulee | B39: Gato de Irgadriel | C39: Pasajero | E39: {=IFERROR(INDEX(Hospedaje!$A$2:$A$32, MATCH(TRUE, BYROW(Hospedaje!$E$2:$S$32, LAMBDA(fila, COUNTIF(fila, A39)>0)), 0)),"-")} -> - | F39: 1 | G39: 0 | I39: =IF(COUNTIF(Hospedaje!$E$2:$S$32,A39)=1,"Sí",IF(COUNTIF(Hospedaje!$E$2:$S$32,A39)=0,"No","DUPLICADO")) -> No | J39: Guarda | K39: Explorador nocturno | L39: Batidor | AD39: Pasajero
A40: Osezno | C40: Pasajero | E40: {=IFERROR(INDEX(Hospedaje!$A$2:$A$32, MATCH(TRUE, BYROW(Hospedaje!$E$2:$S$32, LAMBDA(fila, COUNTIF(fila, A40)>0)), 0)),"-")} -> Zoo | F40: 1 | G40: 0.5 | I40: =IF(COUNTIF(Hospedaje!$E$2:$S$32,A40)=1,"Sí",IF(COUNTIF(Hospedaje!$E$2:$S$32,A40)=0,"No","DUPLICADO")) -> Sí | J40: Explorador nocturno | K40: Batidor | AD40: Pasajero
...

Sheet Carros
A1: Carro | D1: Aguante | J1: Propulsión | P1: Consumo | S1: Pasajeros | V1: Carga
D2: PG | G2: Dureza | J2: Fuerza | M2: Criaturas máxima
A3: Nombre | B3: Tipo Carro | C3: Mejoras | D3: TOTAL | E3: Base | F3: Mejora | G3: TOTAL | H3: Base | I3: Mejora | J3: TOTAL | K3: Base | L3: Mejora | M3: TOTAL | N3: Base | O3: Mejora | P3: TOTAL | Q3: Base | R3: Mejora | S3: TOTAL | T3: Base | U3: Mejora | V3: TOTAL | W3: Base | X3: Mejora
A4: Viajeros 1 | B4: Carro de viajeros | D4: =E4+F4 -> 60 | E4: =IFERROR(VLOOKUP(B4,'Lista Carros'!$A$3:$K$26, 3, FALSE),0) -> 60 | G4: =H4+I4 -> 5 | H4: =IFERROR(VLOOKUP(B4,'Lista Carros'!$A$3:$K$26, 4, FALSE),0) -> 5 | J4: =K4+L4 -> 10 | K4: =IFERROR(VLOOKUP(B4,'Lista Carros'!$A$3:$K$26, 5, FALSE),0) -> 10 | M4: =N4+O4 -> 2 | N4: =IFERROR(VLOOKUP(B4,'Lista Carros'!$A$3:$K$26, 6, FALSE),0) -> 2 | P4: =Q4+R4 -> 2 | Q4: =IFERROR(VLOOKUP(B4,'Lista Carros'!$A$3:$K$26, 8, FALSE),0) -> 2 | S4: =T4+U4 -> 8 | T4: =IFERROR(VLOOKUP(B4,'Lista Carros'!$A$3:$K$26, 9, FALSE),0) -> 8 | V4: =W4+X4 -> 5 | W4: =IFERROR(VLOOKUP(B4,'Lista Carros'!$A$3:$K$26, 10, FALSE),0) -> 4 | X4: =TRUNC(W4*0.3) -> 1
A5: Viajeros 2 | B5: Carro de viajeros | D5: =E5+F5 -> 60 | E5: =IFERROR(VLOOKUP(B5,'Lista Carros'!$A$3:$K$26, 3, FALSE),0) -> 60 | G5: =H5+I5 -> 5 | H5: =IFERROR(VLOOKUP(B5,'Lista Carros'!$A$3:$K$26, 4, FALSE),0) -> 5 | J5: =K5+L5 -> 10 | K5: =IFERROR(VLOOKUP(B5,'Lista Carros'!$A$3:$K$26, 5, FALSE),0) -> 10 | M5: =N5+O5 -> 2 | N5: =IFERROR(VLOOKUP(B5,'Lista Carros'!$A$3:$K$26, 6, FALSE),0) -> 2 | P5: =Q5+R5 -> 2 | Q5: =IFERROR(VLOOKUP(B5,'Lista Carros'!$A$3:$K$26, 8, FALSE),0) -> 2 | S5: =T5+U5 -> 8 | T5: =IFERROR(VLOOKUP(B5,'Lista Carros'!$A$3:$K$26, 9, FALSE),0) -> 8 | V5: =W5+X5 -> 5 | W5: =IFERROR(VLOOKUP(B5,'Lista Carros'!$A$3:$K$26, 10, FALSE),0) -> 4 | X5: =TRUNC(W5*0.3) -> 1
A6: Viajeros 3 | B6: Carro de viajeros | D6: =E6+F6 -> 60 | E6: =IFERROR(VLOOKUP(B6,'Lista Carros'!$A$3:$K$26, 3, FALSE),0) -> 60 | G6: =H6+I6 -> 5 | H6: =IFERROR(VLOOKUP(B6,'Lista Carros'!$A$3:$K$26, 4, FALSE),0) -> 5 | J6: =K6+L6 -> 10 | K6: =IFERROR(VLOOKUP(B6,'Lista Carros'!$A$3:$K$26, 5, FALSE),0) -> 10 | M6: =N6+O6 -> 2 | N6: =IFERROR(VLOOKUP(B6,'Lista Carros'!$A$3:$K$26, 6, FALSE),0) -> 2 | P6: =Q6+R6 -> 2 | Q6: =IFERROR(VLOOKUP(B6,'Lista Carros'!$A$3:$K$26, 8, FALSE),0) -> 2 | S6: =T6+U6 -> 8 | T6: =IFERROR(VLOOKUP(B6,'Lista Carros'!$A$3:$K$26, 9, FALSE),0) -> 8 | V6: =W6+X6 -> 5 | W6: =IFERROR(VLOOKUP(B6,'Lista Carros'!$A$3:$K$26, 10, FALSE),0) -> 4 | X6: =TRUNC(W6*0.3) -> 1
A7: Viajeros 4 | B7: Carro de viajeros | D7: =E7+F7 -> 60 | E7: =IFERROR(VLOOKUP(B7,'Lista Carros'!$A$3:$K$26, 3, FALSE),0) -> 60 | G7: =H7+I7 -> 5 | H7: =IFERROR(VLOOKUP(B7,'Lista Carros'!$A$3:$K$26, 4, FALSE),0) -> 5 | J7: =K7+L7 -> 10 | K7: =IFERROR(VLOOKUP(B7,'Lista Carros'!$A$3:$K$26, 5, FALSE),0) -> 10 | M7: =N7+O7 -> 2 | N7: =IFERROR(VLOOKUP(B7,'Lista Carros'!$A$3:$K$26, 6, FALSE),0) -> 2 | P7: =Q7+R7 -> 2 | Q7: =IFERROR(VLOOKUP(B7,'Lista Carros'!$A$3:$K$26, 8, FALSE),0) -> 2 | S7: =T7+U7 -> 8 | T7: =IFERROR(VLOOKUP(B7,'Lista Carros'!$A$3:$K$26, 9, FALSE),0) -> 8 | V7: =W7+X7 -> 5 | W7: =IFERROR(VLOOKUP(B7,'Lista Carros'!$A$3:$K$26, 10, FALSE),0) -> 4 | X7: =TRUNC(W7*0.3) -> 1
A8: Viajeros 5 | B8: Carro de viajeros | D8: =E8+F8 -> 60 | E8: =IFERROR(VLOOKUP(B8,'Lista Carros'!$A$3:$K$26, 3, FALSE),0) -> 60 | G8: =H8+I8 -> 5 | H8: =IFERROR(VLOOKUP(B8,'Lista Carros'!$A$3:$K$26, 4, FALSE),0) -> 5 | J8: =K8+L8 -> 10 | K8: =IFERROR(VLOOKUP(B8,'Lista Carros'!$A$3:$K$26, 5, FALSE),0) -> 10 | M8: =N8+O8 -> 2 | N8: =IFERROR(VLOOKUP(B8,'Lista Carros'!$A$3:$K$26, 6, FALSE),0) -> 2 | P8: =Q8+R8 -> 2 | Q8: =IFERROR(VLOOKUP(B8,'Lista Carros'!$A$3:$K$26, 8, FALSE),0) -> 2 | S8: =T8+U8 -> 8 | T8: =IFERROR(VLOOKUP(B8,'Lista Carros'!$A$3:$K$26, 9, FALSE),0) -> 8 | V8: =W8+X8 -> 5 | W8: =IFERROR(VLOOKUP(B8,'Lista Carros'!$A$3:$K$26, 10, FALSE),0) -> 4 | X8: =TRUNC(W8*0.3) -> 1
A9: Prisioneros | B9: Carro de prisioneros | D9: =E9+F9 -> 60 | E9: =IFERROR(VLOOKUP(B9,'Lista Carros'!$A$3:$K$26, 3, FALSE),0) -> 60 | G9: =H9+I9 -> 5 | H9: =IFERROR(VLOOKUP(B9,'Lista Carros'!$A$3:$K$26, 4, FALSE),0) -> 5 | J9: =K9+L9 -> 5 | K9: =IFERROR(VLOOKUP(B9,'Lista Carros'!$A$3:$K$26, 5, FALSE),0) -> 5 | M9: =N9+O9 -> 1 | N9: =IFERROR(VLOOKUP(B9,'Lista Carros'!$A$3:$K$26, 6, FALSE),0) -> 1 | P9: =Q9+R9 -> 2 | Q9: =IFERROR(VLOOKUP(B9,'Lista Carros'!$A$3:$K$26, 8, FALSE),0) -> 2 | S9: =T9+U9 -> 10 | T9: =IFERROR(VLOOKUP(B9,'Lista Carros'!$A$3:$K$26, 9, FALSE),0) -> 10 | V9: =W9+X9 -> 2 | W9: =IFERROR(VLOOKUP(B9,'Lista Carros'!$A$3:$K$26, 10, FALSE),0) -> 2 | X9: =TRUNC(W9*0.3) -> 0
A10: Zoo | B10: Carro zoológico | D10: =E10+F10 -> 60 | E10: =IFERROR(VLOOKUP(B10,'Lista Carros'!$A$3:$K$26, 3, FALSE),0) -> 60 | G10: =H10+I10 -> 5 | H10: =IFERROR(VLOOKUP(B10,'Lista Carros'!$A$3:$K$26, 4, FALSE),0) -> 5 | J10: =K10+L10 -> 5 | K10: =IFERROR(VLOOKUP(B10,'Lista Carros'!$A$3:$K$26, 5, FALSE),0) -> 5 | M10: =N10+O10 -> 1 | N10: =IFERROR(VLOOKUP(B10,'Lista Carros'!$A$3:$K$26, 6, FALSE),0) -> 1 | P10: =Q10+R10 -> 2 | Q10: =IFERROR(VLOOKUP(B10,'Lista Carros'!$A$3:$K$26, 8, FALSE),0) -> 2 | S10: =T10+U10 -> 10 | T10: =IFERROR(VLOOKUP(B10,'Lista Carros'!$A$3:$K$26, 9, FALSE),0) -> 10 | V10: =W10+X10 -> 2 | W10: =IFERROR(VLOOKUP(B10,'Lista Carros'!$A$3:$K$26, 10, FALSE),0) -> 2 | X10: =TRUNC(W10*0.3) -> 0
A11: Familias Kalsgard | B11: Carruaje familiar | D11: =E11+F11 -> 60 | E11: =IFERROR(VLOOKUP(B11,'Lista Carros'!$A$3:$K$26, 3, FALSE),0) -> 60 | G11: =H11+I11 -> 5 | H11: =IFERROR(VLOOKUP(B11,'Lista Carros'!$A$3:$K$26, 4, FALSE),0) -> 5 | J11: =K11+L11 -> 10 | K11: =IFERROR(VLOOKUP(B11,'Lista Carros'!$A$3:$K$26, 5, FALSE),0) -> 10 | M11: =N11+O11 -> 2 | N11: =IFERROR(VLOOKUP(B11,'Lista Carros'!$A$3:$K$26, 6, FALSE),0) -> 2 | P11: =Q11+R11 -> 2 | Q11: =IFERROR(VLOOKUP(B11,'Lista Carros'!$A$3:$K$26, 8, FALSE),0) -> 2 | S11: =T11+U11 -> 6 | T11: =IFERROR(VLOOKUP(B11,'Lista Carros'!$A$3:$K$26, 9, FALSE),0) -> 6 | V11: =W11+X11 -> 5 | W11: =IFERROR(VLOOKUP(B11,'Lista Carros'!$A$3:$K$26, 10, FALSE),0) -> 4 | X11: =TRUNC(W11*0.3) -> 1
A12: Mercancías Hierro | B12: Carro de mercancías | D12: =E12+F12 -> 60 | E12: =IFERROR(VLOOKUP(B12,'Lista Carros'!$A$3:$K$26, 3, FALSE),0) -> 60 | G12: =H12+I12 -> 5 | H12: =IFERROR(VLOOKUP(B12,'Lista Carros'!$A$3:$K$26, 4, FALSE),0) -> 5 | J12: =K12+L12 -> 10 | K12: =IFERROR(VLOOKUP(B12,'Lista Carros'!$A$3:$K$26, 5, FALSE),0) -> 10 | M12: =N12+O12 -> 2 | N12: =IFERROR(VLOOKUP(B12,'Lista Carros'!$A$3:$K$26, 6, FALSE),0) -> 2 | P12: =Q12+R12 -> 1 | Q12: =IFERROR(VLOOKUP(B12,'Lista Carros'!$A$3:$K$26, 8, FALSE),0) -> 1 | S12: =T12+U12 -> 1 | T12: =IFERROR(VLOOKUP(B12,'Lista Carros'!$A$3:$K$26, 9, FALSE),0) -> 1 | V12: =W12+X12 -> 13 | W12: =IFERROR(VLOOKUP(B12,'Lista Carros'!$A$3:$K$26, 10, FALSE),0) -> 10 | X12: =TRUNC(W12*0.3) -> 3
A13: Mercancías General | B13: Carro de mercancías | D13: =E13+F13 -> 60 | E13: =IFERROR(VLOOKUP(B13,'Lista Carros'!$A$3:$K$26, 3, FALSE),0) -> 60 | G13: =H13+I13 -> 5 | H13: =IFERROR(VLOOKUP(B13,'Lista Carros'!$A$3:$K$26, 4, FALSE),0) -> 5 | J13: =K13+L13 -> 10 | K13: =IFERROR(VLOOKUP(B13,'Lista Carros'!$A$3:$K$26, 5, FALSE),0) -> 10 | M13: =N13+O13 -> 2 | N13: =IFERROR(VLOOKUP(B13,'Lista Carros'!$A$3:$K$26, 6, FALSE),0) -> 2 | P13: =Q13+R13 -> 1 | Q13: =IFERROR(VLOOKUP(B13,'Lista Carros'!$A$3:$K$26, 8, FALSE),0) -> 1 | S13: =T13+U13 -> 1 | T13: =IFERROR(VLOOKUP(B13,'Lista Carros'!$A$3:$K$26, 9, FALSE),0) -> 1 | V13: =W13+X13 -> 13 | W13: =IFERROR(VLOOKUP(B13,'Lista Carros'!$A$3:$K$26, 10, FALSE),0) -> 10 | X13: =TRUNC(W13*0.3) -> 3
A14: Mercancías Punta Arena | B14: Carro de mercancías | D14: =E14+F14 -> 60 | E14: =IFERROR(VLOOKUP(B14,'Lista Carros'!$A$3:$K$26, 3, FALSE),0) -> 60 | G14: =H14+I14 -> 5 | H14: =IFERROR(VLOOKUP(B14,'Lista Carros'!$A$3:$K$26, 4, FALSE),0) -> 5 | J14: =K14+L14 -> 10 | K14: =IFERROR(VLOOKUP(B14,'Lista Carros'!$A$3:$K$26, 5, FALSE),0) -> 10 | M14: =N14+O14 -> 2 | N14: =IFERROR(VLOOKUP(B14,'Lista Carros'!$A$3:$K$26, 6, FALSE),0) -> 2 | P14: =Q14+R14 -> 1 | Q14: =IFERROR(VLOOKUP(B14,'Lista Carros'!$A$3:$K$26, 8, FALSE),0) -> 1 | S14: =T14+U14 -> 1 | T14: =IFERROR(VLOOKUP(B14,'Lista Carros'!$A$3:$K$26, 9, FALSE),0) -> 1 | V14: =W14+X14 -> 13 | W14: =IFERROR(VLOOKUP(B14,'Lista Carros'!$A$3:$K$26, 10, FALSE),0) -> 10 | X14: =TRUNC(W14*0.3) -> 3
A15: Mercancías Kalsgard | B15: Carro de mercancías específicas | D15: =E15+F15 -> 60 | E15: =IFERROR(VLOOKUP(B15,'Lista Carros'!$A$3:$K$26, 3, FALSE),0) -> 60 | G15: =H15+I15 -> 5 | H15: =IFERROR(VLOOKUP(B15,'Lista Carros'!$A$3:$K$26, 4, FALSE),0) -> 5 | J15: =K15+L15 -> 10 | K15: =IFERROR(VLOOKUP(B15,'Lista Carros'!$A$3:$K$26, 5, FALSE),0) -> 10 | M15: =N15+O15 -> 2 | N15: =IFERROR(VLOOKUP(B15,'Lista Carros'!$A$3:$K$26, 6, FALSE),0) -> 2 | P15: =Q15+R15 -> 1 | Q15: =IFERROR(VLOOKUP(B15,'Lista Carros'!$A$3:$K$26, 8, FALSE),0) -> 1 | S15: =T15+U15 -> 1 | T15: =IFERROR(VLOOKUP(B15,'Lista Carros'!$A$3:$K$26, 9, FALSE),0) -> 1 | V15: =W15+X15 -> 26 | W15: =IFERROR(VLOOKUP(B15,'Lista Carros'!$A$3:$K$26, 10, FALSE),0) -> 20 | X15: =TRUNC(W15*0.3) -> 6
... A27: Bar sin límites | B27: Carro taberna | D27: =E27+F27 -> 60 | E27: =IFERROR(VLOOKUP(B27,'Lista Carros'!$A$3:$K$26, 3, FALSE),0) -> 60 | G27: =H27+I27 -> 5 | H27: =IFERROR(VLOOKUP(B27,'Lista Carros'!$A$3:$K$26, 4, FALSE),0) -> 5 | J27: =K27+L27 -> 10 | K27: =IFERROR(VLOOKUP(B27,'Lista Carros'!$A$3:$K$26, 5, FALSE),0) -> 10 | M27: =N27+O27 -> 2 | N27: =IFERROR(VLOOKUP(B27,'Lista Carros'!$A$3:$K$26, 6, FALSE),0) -> 2 | P27: =Q27+R27 -> 2 | Q27: =IFERROR(VLOOKUP(B27,'Lista Carros'!$A$3:$K$26, 8, FALSE),0) -> 2 | S27: =T27+U27 -> 3 | T27: =IFERROR(VLOOKUP(B27,'Lista Carros'!$A$3:$K$26, 9, FALSE),0) -> 3 | V27: =W27+X27 -> 6 | W27: =IFERROR(VLOOKUP(B27,'Lista Carros'!$A$3:$K$26, 10, FALSE),0) -> 5 | X27: =TRUNC(W27*0.3) -> 1
A28: Cómodo 1 | B28: Carruaje cómodo | C28: Acorazado, espacio ampliado (viajeros) | D28: =E28+F28 -> 90 | E28: =IFERROR(VLOOKUP(B28,'Lista Carros'!$A$3:$K$26, 3, FALSE),0) -> 60 | F28: =E28*0.5 -> 30 | G28: =H28+I28 -> 10 | H28: =IFERROR(VLOOKUP(B28,'Lista Carros'!$A$3:$K$26, 4, FALSE),0) -> 5 | I28: 5 | J28: =K28+L28 -> 14 | K28: =IFERROR(VLOOKUP(B28,'Lista Carros'!$A$3:$K$26, 5, FALSE),0) -> 6 | L28: =K28+2 -> 8 | M28: =N28+O28 -> 2 | N28: =IFERROR(VLOOKUP(B28,'Lista Carros'!$A$3:$K$26, 6, FALSE),0) -> 1 | O28: 1 | P28: =Q28+R28 -> 2 | Q28: =IFERROR(VLOOKUP(B28,'Lista Carros'!$A$3:$K$26, 8, FALSE),0) -> 1 | R28: 1 | S28: =T28+U28 -> 5 | T28: =IFERROR(VLOOKUP(B28,'Lista Carros'!$A$3:$K$26, 9, FALSE),0) -> 4 | U28: =TRUNC(T28*0.25) -> 1 | V28: =W28+X28 -> 5 | W28: =IFERROR(VLOOKUP(B28,'Lista Carros'!$A$3:$K$26, 10, FALSE),0) -> 4 | X28: =TRUNC(W28*0.3) -> 1
A29: Cómodo 2 | B29: Carruaje cómodo | C29: Acorazado, espacio ampliado (viajeros) | D29: =E29+F29 -> 90 | E29: =IFERROR(VLOOKUP(B29,'Lista Carros'!$A$3:$K$26, 3, FALSE),0) -> 60 | F29: =E29*0.5 -> 30 | G29: =H29+I29 -> 10 | H29: =IFERROR(VLOOKUP(B29,'Lista Carros'!$A$3:$K$26, 4, FALSE),0) -> 5 | I29: 5 | J29: =K29+L29 -> 14 | K29: =IFERROR(VLOOKUP(B29,'Lista Carros'!$A$3:$K$26, 5, FALSE),0) -> 6 | L29: =K29+2 -> 8 | M29: =N29+O29 -> 2 | N29: =IFERROR(VLOOKUP(B29,'Lista Carros'!$A$3:$K$26, 6, FALSE),0) -> 1 | O29: 1 | P29: =Q29+R29 -> 2 | Q29: =IFERROR(VLOOKUP(B29,'Lista Carros'!$A$3:$K$26, 8, FALSE),0) -> 1 | R29: 1 | S29: =T29+U29 -> 5 | T29: =IFERROR(VLOOKUP(B29,'Lista Carros'!$A$3:$K$26, 9, FALSE),0) -> 4 | U29: =TRUNC(T29*0.25) -> 1 | V29: =W29+X29 -> 5 | W29: =IFERROR(VLOOKUP(B29,'Lista Carros'!$A$3:$K$26, 10, FALSE),0) -> 4 | X29: =TRUNC(W29*0.3) -> 1
A30: Real | B30: Carruaje real | C30: Acorazado | D30: =E30+F30 -> 120 | E30: =IFERROR(VLOOKUP(B30,'Lista Carros'!$A$3:$K$26, 3, FALSE),0) -> 80 | F30: =E30*0.5 -> 40 | G30: =H30+I30 -> 10 | H30: =IFERROR(VLOOKUP(B30,'Lista Carros'!$A$3:$K$26, 4, FALSE),0) -> 5 | I30: 5 | J30: =K30+L30 -> 18 | K30: =IFERROR(VLOOKUP(B30,'Lista Carros'!$A$3:$K$26, 5, FALSE),0) -> 8 | L30: =K30+2 -> 10 | M30: =N30+O30 -> 4 | N30: =IFERROR(VLOOKUP(B30,'Lista Carros'!$A$3:$K$26, 6, FALSE),0) -> 2 | O30: 2 | P30: =Q30+R30 -> 2 | Q30: =IFERROR(VLOOKUP(B30,'Lista Carros'!$A$3:$K$26, 8, FALSE),0) -> 2 | S30: =T30+U30 -> 3 | T30: =IFERROR(VLOOKUP(B30,'Lista Carros'!$A$3:$K$26, 9, FALSE),0) -> 3 | V30: =W30+X30 -> 2 | W30: =IFERROR(VLOOKUP(B30,'Lista Carros'!$A$3:$K$26, 10, FALSE),0) -> 2 | X30: =TRUNC(W30*0.3) -> 0
A31: Viajeros grande | B31: Carro de viajeros | C31: Espacio ampliado (viajero) | D31: =E31+F31 -> 60 | E31: =IFERROR(VLOOKUP(B31,'Lista Carros'!$A$3:$K$26, 3, FALSE),0) -> 60 | G31: =H31+I31 -> 5 | H31: =IFERROR(VLOOKUP(B31,'Lista Carros'!$A$3:$K$26, 4, FALSE),0) -> 5 | J31: =K31+L31 -> 12 | K31: =IFERROR(VLOOKUP(B31,'Lista Carros'!$A$3:$K$26, 5, FALSE),0) -> 10 | L31: 2 | M31: =N31+O31 -> 2 | N31: =IFERROR(VLOOKUP(B31,'Lista Carros'!$A$3:$K$26, 6, FALSE),0) -> 2 | P31: =Q31+R31 -> 2 | Q31: =IFERROR(VLOOKUP(B31,'Lista Carros'!$A$3:$K$26, 8, FALSE),0) -> 2 | S31: =T31+U31 -> 10 | T31: =IFERROR(VLOOKUP(B31,'Lista Carros'!$A$3:$K$26, 9, FALSE),0) -> 8 | U31: =TRUNC(T31*0.25) -> 2 | V31: =W31+X31 -> 5 | W31: =IFERROR(VLOOKUP(B31,'Lista Carros'!$A$3:$K$26, 10, FALSE),0) -> 4 | X31: =TRUNC(W31*0.3) -> 1
D32: =E32+F32 -> 0 | E32: =IFERROR(VLOOKUP(B32,'Lista Carros'!$A$3:$K$26, 3, FALSE),0) -> 0 | G32: =H32+I32 -> 0 | H32: =IFERROR(VLOOKUP(B32,'Lista Carros'!$A$3:$K$26, 4, FALSE),0) -> 0 | J32: =K32+L32 -> 0 | K32: =IFERROR(VLOOKUP(B32,'Lista Carros'!$A$3:$K$26, 5, FALSE),0) -> 0 | M32: =N32+O32 -> 0 | N32: =IFERROR(VLOOKUP(B32,'Lista Carros'!$A$3:$K$26, 6, FALSE),0) -> 0 | P32: =Q32+R32 -> 0 | Q32: =IFERROR(VLOOKUP(B32,'Lista Carros'!$A$3:$K$26, 8, FALSE),0) -> 0 | S32: =T32+U32 -> 0 | T32: =IFERROR(VLOOKUP(B32,'Lista Carros'!$A$3:$K$26, 9, FALSE),0) -> 0 | V32: =W32+X32 -> 0 | W32: =IFERROR(VLOOKUP(B32,'Lista Carros'!$A$3:$K$26, 10, FALSE),0) -> 0 | X32: =TRUNC(W32*0.3) -> 0
D33: =E33+F33 -> 0 | E33: =IFERROR(VLOOKUP(B33,'Lista Carros'!$A$3:$K$26, 3, FALSE),0) -> 0 | G33: =H33+I33 -> 0 | H33: =IFERROR(VLOOKUP(B33,'Lista Carros'!$A$3:$K$26, 4, FALSE),0) -> 0 | J33: =K33+L33 -> 0 | K33: =IFERROR(VLOOKUP(B33,'Lista Carros'!$A$3:$K$26, 5, FALSE),0) -> 0 | M33: =N33+O33 -> 0 | N33: =IFERROR(VLOOKUP(B33,'Lista Carros'!$A$3:$K$26, 6, FALSE),0) -> 0 | P33: =Q33+R33 -> 0 | Q33: =IFERROR(VLOOKUP(B33,'Lista Carros'!$A$3:$K$26, 8, FALSE),0) -> 0 | S33: =T33+U33 -> 0 | T33: =IFERROR(VLOOKUP(B33,'Lista Carros'!$A$3:$K$26, 9, FALSE),0) -> 0 | V33: =W33+X33 -> 0 | W33: =IFERROR(VLOOKUP(B33,'Lista Carros'!$A$3:$K$26, 10, FALSE),0) -> 0 | X33: =TRUNC(W33*0.3) -> 0
D34: =E34+F34 -> 0 | E34: =IFERROR(VLOOKUP(B34,'Lista Carros'!$A$3:$K$26, 3, FALSE),0) -> 0 | G34: =H34+I34 -> 0 | H34: =IFERROR(VLOOKUP(B34,'Lista Carros'!$A$3:$K$26, 4, FALSE),0) -> 0 | J34: =K34+L34 -> 0 | K34: =IFERROR(VLOOKUP(B34,'Lista Carros'!$A$3:$K$26, 5, FALSE),0) -> 0 | M34: =N34+O34 -> 0 | N34: =IFERROR(VLOOKUP(B34,'Lista Carros'!$A$3:$K$26, 6, FALSE),0) -> 0 | P34: =Q34+R34 -> 0 | Q34: =IFERROR(VLOOKUP(B34,'Lista Carros'!$A$3:$K$26, 8, FALSE),0) -> 0 | S34: =T34+U34 -> 0 | T34: =IFERROR(VLOOKUP(B34,'Lista Carros'!$A$3:$K$26, 9, FALSE),0) -> 0 | V34: =W34+X34 -> 0 | W34: =IFERROR(VLOOKUP(B34,'Lista Carros'!$A$3:$K$26, 10, FALSE),0) -> 0 | X34: =TRUNC(W34*0.3) -> 0

Sheet Hospedaje
A1: Carro | B1: Pasajeros máximo | C1: Pasajeros actuales | D1: Consumo por pasajeros | E1: 1 | F1: =E1+1 -> 2 | G1: =F1+1 -> 3 | H1: =G1+1 -> 4 | I1: =H1+1 -> 5 | J1: =I1+1 -> 6 | K1: =J1+1 -> 7 | L1: =K1+1 -> 8 | M1: =L1+1 -> 9 | ... S1: =R1+1 -> 15
A2: =Caravana!A4 -> Viajeros 1 | B2: =IFERROR(VLOOKUP($A2,Carros!$1:$34, 19, FALSE),"") -> 8 | C2: ='Ocupación Carro-Viajeros'!B2 -> 8 | D2: ='Consumo Carro-Viajeros'!B2 -> 8 | E2: Bevelek | F2: Vankor | G2: Velani Korrast | H2: Seya Numari | I2: Ormund Gevren | J2: Caurrin Whesterwill | K2: krixi cincadientes | L2: Conduct random 6
A3: =Caravana!A5 -> Viajeros 2 | B3: =IFERROR(VLOOKUP($A3,Carros!$1:$34, 19, FALSE),"") -> 8 | C3: ='Ocupación Carro-Viajeros'!B3 -> 7 | D3: ='Consumo Carro-Viajeros'!B3 -> 7 | E3: Halvard Kaelvik | F3: Perrin Holbrook | G3: Eilvarr | H3: Brindelvasthimir Quillopon Dranzibandor | I3: Conduct random 5 | J3: Conduct random 7 | K3: Akane
A4: =Caravana!A6 -> Viajeros 3 | B4: =IFERROR(VLOOKUP($A4,Carros!$1:$34, 19, FALSE),"") -> 8 | C4: ='Ocupación Carro-Viajeros'!B4 -> 7 | D4: ='Consumo Carro-Viajeros'!B4 -> 7 | E4: Ramaso Panor | F4: Conduct random 1 | G4: Conduct random 4 | H4: Conduct random 8 | I4: Conduct random 11 | J4: Agricultor random 1 | K4: Agricultor random 2
A5: =Caravana!A7 -> Viajeros 4 | B5: =IFERROR(VLOOKUP($A5,Carros!$1:$34, 19, FALSE),"") -> 8 | C5: ='Ocupación Carro-Viajeros'!B5 -> 7 | D5: ='Consumo Carro-Viajeros'!B5 -> 7 | E5: Selanza Rovari | F5: Dominic Torettoson | G5: Conduct random 2 | H5: Conduct random 9 | I5: Conduct random 12 | J5: Uksahkka | K5: Soki Mogu
A6: =Caravana!A8 -> Viajeros 5 | B6: =IFERROR(VLOOKUP($A6,Carros!$1:$34, 19, FALSE),"") -> 8 | C6: ='Ocupación Carro-Viajeros'!B6 -> 6 | D6: ='Consumo Carro-Viajeros'!B6 -> 6 | E6: Inuliak | F6: Odval | G6: Shuo | H6: Conduct random 3 | I6: Conduct random 10 | J6: Korrin Feldane
A7: =Caravana!A9 -> Prisioneros | B7: =IFERROR(VLOOKUP($A7,Carros!$1:$34, 19, FALSE),"") -> 10 | C7: ='Ocupación Carro-Viajeros'!B7 -> 0 | D7: ='Consumo Carro-Viajeros'!B7 -> 0
A8: =Caravana!A10 -> Zoo | B8: =IFERROR(VLOOKUP($A8,Carros!$1:$34, 19, FALSE),"") -> 10 | C8: ='Ocupación Carro-Viajeros'!B8 -> 8.5 | D8: ='Consumo Carro-Viajeros'!B8 -> 1 | E8: caballos Yakutos | F8: Yak | G8: osezno | H8: Thriss
A9: =Caravana!A11 -> Familias Kalsgard | B9: =IFERROR(VLOOKUP($A9,Carros!$1:$34, 19, FALSE),"") -> 6 | C9: ='Ocupación Carro-Viajeros'!B9 -> 6.5 | D9: ='Consumo Carro-Viajeros'!B9 -> 8 | E9: Hargor Hagorsson | F9: Siv Hagorsson | G9: Torvald Hagorsson | H9: Inga Hagorsson | I9: Leif Hagorsson | J9: Hayashi Tomoko | K9: Daichi Tomoko | L9: Aiko Tomoko
A10: =Caravana!A12 -> Mercancías Hierro | B10: =IFERROR(VLOOKUP($A10,Carros!$1:$34, 19, FALSE),"") -> 1 | C10: ='Ocupación Carro-Viajeros'!B10 -> 0 | D10: ='Consumo Carro-Viajeros'!B10 -> 0
A11: =Caravana!A13 -> Mercancías General | B11: =IFERROR(VLOOKUP($A11,Carros!$1:$34, 19, FALSE),"") -> 1 | C11: ='Ocupación Carro-Viajeros'!B11 -> 0 | D11: ='Consumo Carro-Viajeros'!B11 -> 0
A12: =Caravana!A14 -> Mercancías Punta Arena | B12: =IFERROR(VLOOKUP($A12,Carros!$1:$34, 19, FALSE),"") -> 1 | C12: ='Ocupación Carro-Viajeros'!B12 -> 0 | D12: ='Consumo Carro-Viajeros'!B12 -> 0
A13: =Caravana!A15 -> Mercancías Kalsgard | B13: =IFERROR(VLOOKUP($A13,Carros!$1:$34, 19, FALSE),"") -> 1 | C13: ='Ocupación Carro-Viajeros'!B13 -> 0 | D13: ='Consumo Carro-Viajeros'!B13 -> 0
A14: =Caravana!A16 -> Carbón | B14: =IFERROR(VLOOKUP($A14,Carros!$1:$34, 19, FALSE),"") -> 1 | C14: ='Ocupación Carro-Viajeros'!B14 -> 0 | D14: ='Consumo Carro-Viajeros'!B14 -> 0
A15: =Caravana!A17 -> Queso | B15: =IFERROR(VLOOKUP($A15,Carros!$1:$34, 19, FALSE),"") -> 1 | C15: ='Ocupación Carro-Viajeros'!B15 -> 1 | D15: ='Consumo Carro-Viajeros'!B15 -> 1 | E15: Asmund (el quesero)
A16: =Caravana!A18 -> Suministros 1 | B16: =IFERROR(VLOOKUP($A16,Carros!$1:$34, 19, FALSE),"") -> 1 | C16: ='Ocupación Carro-Viajeros'!B16 -> 0 | D16: ='Consumo Carro-Viajeros'!B16 -> 0
A17: =Caravana!A19 -> Suministros 2 | B17: =IFERROR(VLOOKUP($A17,Carros!$1:$34, 19, FALSE),"") -> 1 | C17: ='Ocupación Carro-Viajeros'!B17 -> 0 | D17: ='Consumo Carro-Viajeros'!B17 -> 0
A18: =Caravana!A20 -> Koya | B18: =IFERROR(VLOOKUP($A18,Carros!$1:$34, 19, FALSE),"") -> 1 | C18: ='Ocupación Carro-Viajeros'!B18 -> 1 | D18: ='Consumo Carro-Viajeros'!B18 -> 1 | E18: Koya | F18: Spivey
A19: =Caravana!A21 -> Taller | B19: =IFERROR(VLOOKUP($A19,Carros!$1:$34, 19, FALSE),"") -> 2 | C19: ='Ocupación Carro-Viajeros'!B19 -> 0 | D19: ='Consumo Carro-Viajeros'!B19 -> 0
A20: =Caravana!A22 -> Escuela | B20: =IFERROR(VLOOKUP($A20,Carros!$1:$34, 19, FALSE),"") -> 2 | C20: ='Ocupación Carro-Viajeros'!B20 -> 1 | D20: ='Consumo Carro-Viajeros'!B20 -> 1 | E20: Erivo
A21: =Caravana!A23 -> Huerto Hagorsson | B21: =IFERROR(VLOOKUP($A21,Carros!$1:$34, 19, FALSE),"") -> 2 | C21: ='Ocupación Carro-Viajeros'!B21 -> 0 | D21: ='Consumo Carro-Viajeros'!B21 -> 0
A22: =Caravana!A24 -> Huerto 1 | B22: =IFERROR(VLOOKUP($A22,Carros!$1:$34, 19, FALSE),"") -> 2 | C22: ='Ocupación Carro-Viajeros'!B22 -> 2 | D22: ='Consumo Carro-Viajeros'!B22 -> 2 | E22: Skali (Troi), el puto troll
A23: =Caravana!A25 -> Huerto 2 | B23: =IFERROR(VLOOKUP($A23,Carros!$1:$34, 19, FALSE),"") -> 2 | C23: ='Ocupación Carro-Viajeros'!B23 -> 0 | D23: ='Consumo Carro-Viajeros'!B23 -> 0
A24: =Caravana!A26 -> Hospital | B24: =IFERROR(VLOOKUP($A24,Carros!$1:$34, 19, FALSE),"") -> 6 | C24: ='Ocupación Carro-Viajeros'!B24 -> 0 | D24: ='Consumo Carro-Viajeros'!B24 -> 0
A25: =Caravana!A27 -> Bar sin límites | B25: =IFERROR(VLOOKUP($A25,Carros!$1:$34, 19, FALSE),"") -> 3 | C25: ='Ocupación Carro-Viajeros'!B25 -> 2.5 | D25: ='Consumo Carro-Viajeros'!B25 -> 3 | E25: Ralvio Dorran | F25: Lewis | G25: Clark (perro Lewis)
A26: =Caravana!A28 -> Cómodo 1 | B26: =IFERROR(VLOOKUP($A26,Carros!$1:$34, 19, FALSE),"") -> 5 | C26: ='Ocupación Carro-Viajeros'!B26 -> 4.5 | D26: ='Consumo Carro-Viajeros'!B26 -> 5 | E26: Renji | F26: Sandru | G26: Kelda | H26: Virihane | I26: Perro de Renji | J26: Helgalvar
A27: =Caravana!A29 -> Cómodo 2 | B27: =IFERROR(VLOOKUP($A27,Carros!$1:$34, 19, FALSE),"") -> 5 | C27: ='Ocupación Carro-Viajeros'!B27 -> 4 | D27: ='Consumo Carro-Viajeros'!B27 -> 5 | E27: Irgadriel | F27: Frinn (huérfano) | G27: Skøra (huérfana) | H27: Shalelu | I27: Ulf el Ulfen
A28: =Caravana!A30 -> Real | B28: =IFERROR(VLOOKUP($A28,Carros!$1:$34, 19, FALSE),"") -> 3 | C28: ='Ocupación Carro-Viajeros'!B28 -> 3 | D28: ='Consumo Carro-Viajeros'!B28 -> 4 | E28: Ameiko | F28: Hiriko | G28: O Chin Chin | H28: Devoramundos
A29: =Caravana!A31 -> Viajeros grande | B29: =IFERROR(VLOOKUP($A29,Carros!$1:$34, 19, FALSE),"") -> 10 | C29: ='Ocupación Carro-Viajeros'!B29 -> 9 | D29: ='Consumo Carro-Viajeros'!B29 -> 9 | E29: Eirik "Cuervo Roto" | F29: Takorr Senda Quemada | G29: Jorgaan de la Roca Blanca | H29: Ketaek pasos cortos | I29: Sigmund "Ojos de Hielo" | J29: Yrja Vientonegro | K29: Ashka Cantoceniza | L29: Freydis Manodura | M29: Cholna de las Lluvias
A30: =Caravana!A32 | B30: =IFERROR(VLOOKUP($A30,Carros!$1:$34, 19, FALSE),"") | C30: ='Ocupación Carro-Viajeros'!B30 -> 0 | D30: ='Consumo Carro-Viajeros'!B30 -> 0
A31: =Caravana!A33 | B31: =IFERROR(VLOOKUP($A31,Carros!$1:$34, 19, FALSE),"") | C31: ='Ocupación Carro-Viajeros'!B31 -> 0 | D31: ='Consumo Carro-Viajeros'!B31 -> 0
A32: =Caravana!A34 | B32: =IFERROR(VLOOKUP($A32,Carros!$1:$34, 19, FALSE),"") | C32: ='Ocupación Carro-Viajeros'!B32 -> 0 | D32: ='Consumo Carro-Viajeros'!B32 -> 0

Sheet Carga
A1: Carro | B1: Carga máxima | C1: Carga actual | D1: 1 | E1: =D1+1 -> 2 | F1: =E1+1 -> 3 | G1: =F1+1 -> 4 | H1: =G1+1 -> 5 | I1: =H1+1 -> 6 | J1: =I1+1 -> 7 | K1: =J1+1 -> 8 | L1: =K1+1 -> 9 | ... AG1: =AF1+1 -> 30
A2: =Caravana!A4 -> Viajeros 1 | B2: =IFERROR(VLOOKUP($A2,Carros!$1:$34, 22, FALSE),"") -> 5 | C2: ='Ocupación Carro-Mercancía'!B2 -> 4 | D2: Material de reparaciones | E2: Tienda de campaña de supervivencia | F2: Equipo para climas fríos | G2: Estufa
A3: =Caravana!A5 -> Viajeros 2 | B3: =IFERROR(VLOOKUP($A3,Carros!$1:$34, 22, FALSE),"") -> 5 | C3: ='Ocupación Carro-Mercancía'!B3 -> 3 | D3: Material de reparaciones | E3: Tienda de campaña de supervivencia | F3: Estufa
A4: =Caravana!A6 -> Viajeros 3 | B4: =IFERROR(VLOOKUP($A4,Carros!$1:$34, 22, FALSE),"") -> 5 | C4: ='Ocupación Carro-Mercancía'!B4 -> 3 | D4: Material de reparaciones | E4: Tienda de campaña de supervivencia | F4: Estufa
A5: =Caravana!A7 -> Viajeros 4 | B5: =IFERROR(VLOOKUP($A5,Carros!$1:$34, 22, FALSE),"") -> 5 | C5: ='Ocupación Carro-Mercancía'!B5 -> 4 | D5: Material de reparaciones | E5: Tenderete | F5: Estufa
A6: =Caravana!A8 -> Viajeros 5 | B6: =IFERROR(VLOOKUP($A6,Carros!$1:$34, 22, FALSE),"") -> 5 | C6: ='Ocupación Carro-Mercancía'!B6 -> 4 | D6: Material de reparaciones | E6: Trampas de campamento | F6: Estufa
A7: =Caravana!A9 -> Prisioneros | B7: =IFERROR(VLOOKUP($A7,Carros!$1:$34, 22, FALSE),"") -> 2 | C7: ='Ocupación Carro-Mercancía'!B7 -> 0
A8: =Caravana!A10 -> Zoo | B8: =IFERROR(VLOOKUP($A8,Carros!$1:$34, 22, FALSE),"") -> 2 | C8: ='Ocupación Carro-Mercancía'!B8 -> 0
A9: =Caravana!A11 -> Familias Kalsgard | B9: =IFERROR(VLOOKUP($A9,Carros!$1:$34, 22, FALSE),"") -> 5 | C9: ='Ocupación Carro-Mercancía'!B9 -> 0
A10: =Caravana!A12 -> Mercancías Hierro | B10: =IFERROR(VLOOKUP($A10,Carros!$1:$34, 22, FALSE),"") -> 13 | C10: ='Ocupación Carro-Mercancía'!B10 -> 12 | D10: Hierro | E10: Hierro | F10: Hierro | G10: Hierro | H10: Hierro | I10: Hierro | J10: Hierro | K10: Hierro | L10: Hierro | M10: Hierro | O10: Material de reparaciones | P10: Material de reparaciones
A11: =Caravana!A13 -> Mercancías General | B11: =IFERROR(VLOOKUP($A11,Carros!$1:$34, 22, FALSE),"") -> 13 | C11: ='Ocupación Carro-Mercancía'!B11 -> 13 | D11: Mercancías | E11: Mercancías | F11: Mercancías | G11: Mercancías | H11: Mercancías | I11: Mercancías | J11: Mercancías | K11: Mercancías | L11: Mercancías | M11: Mercancías | N11: Mercancías | O11: Mercancías | P11: Mercancías
A12: =Caravana!A14 -> Mercancías Punta Arena | B12: =IFERROR(VLOOKUP($A12,Carros!$1:$34, 22, FALSE),"") -> 13 | C12: ='Ocupación Carro-Mercancía'!B12 -> 13 | D12: Mercancías locales (Punta Arena) | E12: Mercancías locales (Punta Arena) | F12: Mercancías locales (Punta Arena) | G12: Mercancías locales (Punta Arena) | H12: Mercancías locales (Punta Arena) | I12: Mercancías locales (Punta Arena) | J12: Mercancías locales (Punta Arena) | K12: Mercancías locales (Punta Arena) | L12: Mercancías locales (Punta Arena) | M12: Mercancías locales (Punta Arena) | N12: Mercancías locales (Punta Arena) | O12: Material de reparaciones | P12: Material de reparaciones
A13: =Caravana!A15 -> Mercancías Kalsgard | B13: =IFERROR(VLOOKUP($A13,Carros!$1:$34, 22, FALSE),"") -> 26 | C13: ='Ocupación Carro-Mercancía'!B13 -> 26 | D13: Mercancías locales (Kalsgard) | E13: Mercancías locales (Kalsgard) | F13: Mercancías locales (Kalsgard) | G13: Mercancías locales (Kalsgard) | H13: Mercancías locales (Kalsgard) | I13: Mercancías locales (Kalsgard) | J13: Mercancías locales (Kalsgard) | K13: Mercancías locales (Kalsgard) | L13: Mercancías locales (Kalsgard) | M13: Mercancías locales (Kalsgard) | N13: Mercancías locales (Kalsgard) | O13: Mercancías locales (Kalsgard) | P13: Mercancías locales (Kalsgard) | Q13: Mercancías locales (Kalsgard) | R13: Mercancías locales (Kalsgard) | S13: Mercancías locales (Kalsgard) | T13: Mercancías locales (Kalsgard) | U13: Mercancías locales (Kalsgard) | V13: Mercancías locales (Kalsgard) | W13: Mercancías locales (Kalsgard) | X13: Mercancías locales (Kalsgard) | Y13: Mercancías locales (Kalsgard) | Z13: Mercancías locales (Kalsgard) | AA13: Mercancías locales (Kalsgard) | AB13: Mercancías locales (Kalsgard) | AC13: Mercancías locales (Kalsgard)
A14: =Caravana!A16 -> Carbón | B14: =IFERROR(VLOOKUP($A14,Carros!$1:$34, 22, FALSE),"") -> 26 | C14: ='Ocupación Carro-Mercancía'!B14 -> 26 | D14: Carbón (consumible) | E14: Carbón (consumible) | F14: Carbón (consumible) | G14: Carbón (consumible) | H14: Carbón (consumible) | I14: Carbón (consumible) | J14: Carbón (consumible) | K14: Carbón (consumible) | L14: Carbón (consumible) | M14: Carbón (consumible) | N14: Carbón (consumible) | O14: Carbón (consumible) | P14: Carbón (consumible) | Q14: Carbón (consumible) | R14: Carbón (consumible) | S14: Carbón (consumible) | T14: Carbón (consumible) | U14: Carbón (consumible) | V14: Carbón (consumible) | W14: Carbón (consumible) | X14: Carbón (consumible) | Y14: Carbón (consumible) | Z14: Carbón (consumible) | AA14: Carbón (consumible) | AB14: Carbón (consumible) | AC14: Carbón (consumible)
A15: =Caravana!A17 -> Queso | B15: =IFERROR(VLOOKUP($A15,Carros!$1:$34, 22, FALSE),"") -> 26 | C15: ='Ocupación Carro-Mercancía'!B15 -> 20 | D15: Queso | E15: Queso | F15: Queso | G15: Queso | H15: Queso | I15: Queso | J15: Queso | K15: Queso | L15: Queso | M15: Queso | N15: Queso | O15: Queso | P15: Queso | Q15: Queso | R15: Queso | S15: Queso | T15: Queso | U15: Queso | V15: Queso | W15: Queso
A16: =Caravana!A18 -> Suministros 1 | B16: =IFERROR(VLOOKUP($A16,Carros!$1:$34, 22, FALSE),"") -> 26 | C16: ='Ocupación Carro-Mercancía'!B16 -> 4 | D16: Suministros | E16: Suministros | AA16: Suministros | AB16: Suministros
A17: =Caravana!A19 -> Suministros 2 | B17: =IFERROR(VLOOKUP($A17,Carros!$1:$34, 22, FALSE),"") -> 26 | C17: ='Ocupación Carro-Mercancía'!B17 -> 4 | D17: Suministros | E17: Suministros | AA17: Suministros | AB17: Suministros
A18: =Caravana!A20 -> Koya | B18: =IFERROR(VLOOKUP($A18,Carros!$1:$34, 22, FALSE),"") -> 5 | C18: ='Ocupación Carro-Mercancía'!B18 -> 2 | D18: Altar sagrado (Desna) | E18: Altar sagrado (Shelyn)
A19: =Caravana!A21 -> Taller | B19: =IFERROR(VLOOKUP($A19,Carros!$1:$34, 22, FALSE),"") -> 5 | C19: ='Ocupación Carro-Mercancía'!B19 -> 5 | D19: Materiales mágicos diversos | E19: Materiales mágicos diversos | F19: Materiales mágicos diversos | G19: Materiales mágicos diversos | H19: Material para venenos
A20: =Caravana!A22 -> Escuela | B20: =IFERROR(VLOOKUP($A20,Carros!$1:$34, 22, FALSE),"") -> 5 | C20: ='Ocupación Carro-Mercancía'!B20 -> 0
A21: =Caravana!A23 -> Huerto Hagorsson | B21: =IFERROR(VLOOKUP($A21,Carros!$1:$34, 22, FALSE),"") -> 1 | C21: ='Ocupación Carro-Mercancía'!B21 -> 0
A22: =Caravana!A24 -> Huerto 1 | B22: =IFERROR(VLOOKUP($A22,Carros!$1:$34, 22, FALSE),"") -> 1 | C22: ='Ocupación Carro-Mercancía'!B22 -> 0
A23: =Caravana!A25 -> Huerto 2 | B23: =IFERROR(VLOOKUP($A23,Carros!$1:$34, 22, FALSE),"") -> 1 | C23: ='Ocupación Carro-Mercancía'!B23 -> 0
A24: =Caravana!A26 -> Hospital | B24: =IFERROR(VLOOKUP($A24,Carros!$1:$34, 22, FALSE),"") -> 1 | C24: ='Ocupación Carro-Mercancía'!B24 -> 0
A25: =Caravana!A27 -> Bar sin límites | B25: =IFERROR(VLOOKUP($A25,Carros!$1:$34, 22, FALSE),"") -> 6 | C25: ='Ocupación Carro-Mercancía'!B25 -> 3 | D25: Cocina portátil | E25: Cocina portátil | F25: Cocina portátil
A26: =Caravana!A28 -> Cómodo 1 | B26: =IFERROR(VLOOKUP($A26,Carros!$1:$34, 22, FALSE),"") -> 5 | C26: ='Ocupación Carro-Mercancía'!B26 -> 2 | D26: Tesoro 750 | E26: Estufa
A27: =Caravana!A29 -> Cómodo 2 | B27: =IFERROR(VLOOKUP($A27,Carros!$1:$34, 22, FALSE),"") -> 5 | C27: ='Ocupación Carro-Mercancía'!B27 -> 2.5 | D27: Tesoro 750 | E27: Tesoro 400 | F27: Estufa
A28: =Caravana!A30 -> Real | B28: =IFERROR(VLOOKUP($A28,Carros!$1:$34, 22, FALSE),"") -> 2 | C28: ='Ocupación Carro-Mercancía'!B28 -> 1 | D28: Forja portatil | E28: Sello de Amatatsu
A29: =Caravana!A31 -> Viajeros grande | B29: =IFERROR(VLOOKUP($A29,Carros!$1:$34, 22, FALSE),"") -> 5 | C29: ='Ocupación Carro-Mercancía'!B29 -> 0
A30: =Caravana!A32 | B30: =IFERROR(VLOOKUP($A30,Carros!$1:$34, 22, FALSE),"") | C30: ='Ocupación Carro-Mercancía'!B30 -> 0
A31: =Caravana!A33 | B31: =IFERROR(VLOOKUP($A31,Carros!$1:$34, 22, FALSE),"") | C31: ='Ocupación Carro-Mercancía'!B31 -> 0
A32: =Caravana!A34 | B32: =IFERROR(VLOOKUP($A32,Carros!$1:$34, 22, FALSE),"") | C32: ='Ocupación Carro-Mercancía'!B32 -> 0

Sheet Tiro
A1: Carro | B1: Fuerza necesaria | C1: Fuerza actual | D1: Suficiente | E1: Bestias máximas | F1: Bestias actual | G1: 1 | H1: =G1+1 -> 2 | I1: =H1+1 -> 3 | J1: =I1+1 -> 4 | K1: =J1+1 -> 5 | L1: =K1+1 -> 6 | M1: =L1+1 -> 7 | N1: =M1+1 -> 8
A2: =Caravana!A4 -> Viajeros 1 | B2: =IFERROR(VLOOKUP(A2,Carros!$A$4:$O$34,10,FALSE),"") -> 10 | C2: ='Fuerza Carro-Tiro'!B2 -> 28 | D2: =IF(C2>=B2*2,"SUPERA",IF(C2>=B2*1.5,"Excede",IF(C2>=B2,"Supera","Insuficiente"))) -> SUPERA | E2: =IFERROR(VLOOKUP(A2,Carros!$A$4:$O$34,13,FALSE),"") -> 2 | F2: ='Ocupación Carro-Tiro'!B2 -> 2 | G2: Yak | H2: Yak
A3: =Caravana!A5 -> Viajeros 2 | B3: =IFERROR(VLOOKUP(A3,Carros!$A$4:$O$34,10,FALSE),"") -> 10 | C3: ='Fuerza Carro-Tiro'!B3 -> 28 | D3: =IF(C3>=B3*2,"SUPERA",IF(C3>=B3*1.5,"Excede",IF(C3>=B3,"Supera","Insuficiente"))) -> SUPERA | E3: =IFERROR(VLOOKUP(A3,Carros!$A$4:$O$34,13,FALSE),"") -> 2 | F3: ='Ocupación Carro-Tiro'!B3 -> 2 | G3: Yak | H3: Yak
A4: =Caravana!A6 -> Viajeros 3 | B4: =IFERROR(VLOOKUP(A4,Carros!$A$4:$O$34,10,FALSE),"") -> 10 | C4: ='Fuerza Carro-Tiro'!B4 -> 28 | D4: =IF(C4>=B4*2,"SUPERA",IF(C4>=B4*1.5,"Excede",IF(C4>=B4,"Supera","Insuficiente"))) -> SUPERA | E4: =IFERROR(VLOOKUP(A4,Carros!$A$4:$O$34,13,FALSE),"") -> 2 | F4: ='Ocupación Carro-Tiro'!B4 -> 2 | G4: Yak | H4: Yak
A5: =Caravana!A7 -> Viajeros 4 | B5: =IFERROR(VLOOKUP(A5,Carros!$A$4:$O$34,10,FALSE),"") -> 10 | C5: ='Fuerza Carro-Tiro'!B5 -> 28 | D5: =IF(C5>=B5*2,"SUPERA",IF(C5>=B5*1.5,"Excede",IF(C5>=B5,"Supera","Insuficiente"))) -> SUPERA | E5: =IFERROR(VLOOKUP(A5,Carros!$A$4:$O$34,13,FALSE),"") -> 2 | F5: ='Ocupación Carro-Tiro'!B5 -> 2 | G5: Yak | H5: Yak
A6: =Caravana!A8 -> Viajeros 5 | B6: =IFERROR(VLOOKUP(A6,Carros!$A$4:$O$34,10,FALSE),"") -> 10 | C6: ='Fuerza Carro-Tiro'!B6 -> 28 | D6: =IF(C6>=B6*2,"SUPERA",IF(C6>=B6*1.5,"Excede",IF(C6>=B6,"Supera","Insuficiente"))) -> SUPERA | E6: =IFERROR(VLOOKUP(A6,Carros!$A$4:$O$34,13,FALSE),"") -> 2 | F6: ='Ocupación Carro-Tiro'!B6 -> 2 | G6: Yak | H6: Yak
A7: =Caravana!A9 -> Prisioneros | B7: =IFERROR(VLOOKUP(A7,Carros!$A$4:$O$34,10,FALSE),"") -> 5 | C7: ='Fuerza Carro-Tiro'!B7 -> 14 | D7: =IF(C7>=B7*2,"SUPERA",IF(C7>=B7*1.5,"Excede",IF(C7>=B7,"Supera","Insuficiente"))) -> SUPERA | E7: =IFERROR(VLOOKUP(A7,Carros!$A$4:$O$34,13,FALSE),"") -> 1 | F7: ='Ocupación Carro-Tiro'!B7 -> 1 | G7: Yak
A8: =Caravana!A10 -> Zoo | B8: =IFERROR(VLOOKUP(A8,Carros!$A$4:$O$34,10,FALSE),"") -> 5 | C8: ='Fuerza Carro-Tiro'!B8 -> 14 | D8: =IF(C8>=B8*2,"SUPERA",IF(C8>=B8*1.5,"Excede",IF(C8>=B8,"Supera","Insuficiente"))) -> SUPERA | E8: =IFERROR(VLOOKUP(A8,Carros!$A$4:$O$34,13,FALSE),"") -> 1 | F8: ='Ocupación Carro-Tiro'!B8 -> 1 | G8: Yak
A9: =Caravana!A11 -> Familias Kalsgard | B9: =IFERROR(VLOOKUP(A9,Carros!$A$4:$O$34,10,FALSE),"") -> 10 | C9: ='Fuerza Carro-Tiro'!B9 -> 28 | D9: =IF(C9>=B9*2,"SUPERA",IF(C9>=B9*1.5,"Excede",IF(C9>=B9,"Supera","Insuficiente"))) -> SUPERA | E9: =IFERROR(VLOOKUP(A9,Carros!$A$4:$O$34,13,FALSE),"") -> 2 | F9: ='Ocupación Carro-Tiro'!B9 -> 2 | G9: Yak | H9: Yak
A10: =Caravana!A12 -> Mercancías Hierro | B10: =IFERROR(VLOOKUP(A10,Carros!$A$4:$O$34,10,FALSE),"") -> 10 | C10: ='Fuerza Carro-Tiro'!B10 -> 28 | D10: =IF(C10>=B10*2,"SUPERA",IF(C10>=B10*1.5,"Excede",IF(C10>=B10,"Supera","Insuficiente"))) -> SUPERA | E10: =IFERROR(VLOOKUP(A10,Carros!$A$4:$O$34,13,FALSE),"") -> 2 | F10: ='Ocupación Carro-Tiro'!B10 -> 2 | G10: Yak | H10: Yak
